Workbook

Sheet 周报_STD（周一）
B1: 项目管理系统项目工作周报
B2: 编号：
B3: 项目名称 | D3: 项目管理系统标准版 | G3: 本期起止日期 | H3: =日期!B2
B4: 项目阶段 | D4: 项目管理基础功能配置 | G4: 项目状态 | H4: 正常
B5: 阶段目标 | D5: ①平台升级与标准版发布。 ②两级穿透管理功能开发。 ③两级管理部署推进。
A6: 1 | B6: 上期工作综述 | D6: ①70所、201所系统更新部署 ②测试和修改创新院系统（145），准备部署 ③在150更新基础平台，完成交付物模块开发
B7: 本期重点工作 | D7: ①测试和修改创新院系统（145），准备部署 ②在150更新基础平台，完成交付物模块开发 ③DL项目文档修改
B9: =CONCATENATE("上期工作总结（",日期!B3,"）")
B10: 序号 | C10: 名称 | E10: 负责人 | F10: 配合 | G10: 时间 | H10: 任务交付/说明 | I10: 进展说明 | J10: 完成情况
B11: 1 | C11: 201所146-实施部署 ①201系统更新 | E11: 陈伟 | F11: 刘畅 | G11: 2025.08.18-08.22 | H11: 现场部署 | J11: 已完成
B12: 2 | C12: 标准版70所-实施部署 ②国产化环境部署更新 | E12: 陈伟 | F12: 刘畅 | G12: 2025.08.18-08.22 | H12: 现场部署并测试接口 | J12: 已完成
B13: 3 | C13: 创新院145-系统测试 ①功能测试 | E13: 牛栩 | F13: 刘畅 | G13: 2025.08.18-08.20 | H13: 目前共计产出bug58个，未修复33个。 | J13: 进行中
A14: ②组织机构同步的接口开发 | B14: 4 | C14: 创新院145-系统部署 ③发布并打包 | E14: 刘畅 | F14: 陈伟 | G14: 2025.08.20-08.22 | H14: 1）完成145创新院系统更新文档 2）打包代码，制作部署包 3）和创新院约定时间后，去现场部署并调试接口 | J14: 未启动
B15: 5 | C15: 测试版142-功能验证 ②对平台3.2.0新发布的功能进行测试验证 | E15: 刘畅 | F15: 程浩 | G15: 2025.08.20-08.22 | J15: 已完成
B16: 6 | C16: 标准版150-系统开发 ①交付管理功能开发 | E16: 刘畅 | F16: 闫飞、李春阳 | G16: 2025.08.11-08.15 | H16: 1）交付物增删改查 2）交付物反馈 | J16: 已完成
A17: ②组织机构同步的接口开发 | B17: 7 | C17: DL项目-文档编写： ①用户手册V1.0编写 ②软件测试说明V1.0编写 | E17: 刘畅 | F17: 陈伟、牛栩 | G17: 2025.08.11-08.15 | H17: 本周完成V1.0编写 | J17: 已完成
A18: ②组织机构同步的接口开发 | B18: 8 | C18: 201所146-系统集成 ①接口地址配置 ②联调集成 | E18: 陈伟 | F18: 李春阳 | G18: 2025.08.27 | H18: 1）完成现场系统接口配置 2）浪潮已调通项目和计划接口并获取数据 | J18: 已完成
A19: ②组织机构同步的接口开发 | B19: 9 | C19: 标准版150-系统开发 ②集成模块V1.2版本 | E19: 李春阳 | G19: 2025.08.11-08.15 | H19: 1）增强接口校验，防止错误请求导致系统内部错误 2）增强查询条件逻辑，支持数据物理隔离，过滤无需返回的数据 3）修复出现的地址路径错误问题（V1.1显示错误，不影响使用，但易出现错误提示） 4）形成V1.2模型包及运维文档 | J19: 已完成
B21: 上期出现的问题/风险
B22: 序号 | C22: 问题/风险描述 | E22: 可能的影响 | H22: 解决途径和措施
B24: =CONCATENATE("本期工作计划（",日期!B2,"）")
B25: 序号 | C25: 名称 | E25: 负责人 | F25: 配合 | G25: 时间 | H25: 任务交付 | I25: 说明
B26: 1 | C26: 创新院145-系统测试 ①bug处理 | E26: 李鑫 | F26: 闫飞、韩笑、刘畅 | G26: 2025.08.18-08.29 | H26: 上周发现的未修复bug处理
B27: 2 | C27: 创新院145-系统测试 ②功能测试 | E27: 牛栩 | F27: 刘畅 | G27: 2025.08.18-08.29
B28: 3 | C28: 创新院145-系统部署 ③发布并打包 | E28: 陈伟 | F28: 刘畅 | G28: 2025.08.20-08.29 | H28: 测试完成后打包部署
B29: 4 | C29: DL项目-文档编写： ①测试说明、用户说明V2.0版编写提交 | E29: 李翠霞 | F29: 牛栩、刘畅 | G29: 2025.08.25-08.29
B30: 5 | C30: DL项目-集成开发： ②基于上周70所调研情况，讨论在70所的集成接口需求，确定接口实现方案并开发 | E30: 李翠霞 | F30: 李春阳 | G30: 2025.08.25-08.29
B32: 暂时搁置工作
B33: 序号 | C33: 主要内容 | F33: 搁置原因与处理方案 | I33: 预期处理时间 | J33: 负责人
B34: 1 | C34: 创新院145-系统开发 ①完成部门任务中心页面设计 | F34: 以卡片式项目列表为主，搭建部门项目任务中心 等平台上线带权限的统计图功能后再添加统计图 | I34: 2025.05.20 | J34: 刘畅
B35: 2 | C35: 标准版150-系统开发 ②重构任务督办功能 | F35: 1）更名：任务跟踪 2）在创新院145上，把群任务管理更名为督办 | I35: 2025.05.20 | J35: 刘畅
B36: 3 | C36: 201所146-实施部署 ②调通组织机构和人员自动同步接口（创新院系统同步进行） | F36: 1）201所组织机构和人员同步调通 2）创新院系统组织机构和人员同步调通 等数据库弄好了再去201看这个问题 | I36: 2025.05.20 | J36: 杨李凯、陈伟

Sheet 周报_GP（周一）
B1: 项目管理系统项目工作周报
B2: 编号：
B3: 项目名称 | D3: JT版项目管理系统 | G3: 本期起止日期 | H3: =日期!B2
B4: 项目阶段 | D4: 系统周期性优化上线 | G4: 项目状态 | H4: 正常
B5: 阶段目标 | D5: ①经费管理模块配置开发 ②科技项目管理相关功能开发
B6: 上期工作综述 | D6: ①与BKY系统互通测试 ②项目导入接口修改（kj项目，项目重复、单位为空等情况） ③组织主数据查重、对比、合并 ④项目之外其他模块改造升级，支持按分管部分进行隔离（项目动态、风险、问题、合同、涉火试验、质量问题、安全问题等）
B7: 本期重点工作 | D7: ①组织机构的完善 ②BKY系统联调 ③科技项目导入功能、集团成果模块的测试。 ④项目之外其他模块改造升级，支持按分管部分进行隔离（项目动态、风险、问题、合同、涉火试验、质量问题、安全问题等）
B9: =CONCATENATE("上期工作总结（",日期!B3,"）")
B10: 序号 | C10: 名称 | E10: 负责人 | F10: 配合 | G10: 时间 | H10: 任务交付/说明 | I10: 进展说明 | J10: 完成情况
B11: 1 | C11: 系统测试： ①集团版成果模块测试 | E11: 闫飞 | F11: 牛栩 | G11: 2025.08.18-08.22 | H11: 1.功能已完成，因测试写文档，和其他测试任务，待安排测试。 | J11: 进行中
B12: 2 | C12: 系统开发： ①科技项目导入功能完善 | E12: 李鑫 | F12: 闫飞 | G12: 2025.08.18-08.22 | H12: 1.支持导出本单位项目。 2.支持在导出的excel修改后继续导入系统，仅对修改项进行更新。 3.支持导入时对某个字段报错进行提示（由于导入时间过长和异步导入问题此功能可能无法实现） 4.支持根据本单位项目名称进行排查避免重复导入问题。 | J12: 已完成
B13: 3 | C13: 系统开发： ①两级同步系统网络已经调通，完成227到集团数据的报送功能 ②因集团版项目标签改造，两级项目报送增加标签功能 ③录制两级系统演示视频，准备对应的ppt | E13: 李鑫 | F13: 闫飞 | G13: 2025.08.18-08.22 | H13: transfer应用在GCH环境下读取路径存在问题 | J13: 进行中
B14: 4 | C14: 数据梳理： ①对集团版线上组织机构数据对比中台组织机构进行梳理和修改 | E14: 闫飞 | G14: 2025.08.18-08.22 | H14: 线上已有的组织机构已按照中台数据修改。 | J14: 已完成
B15: 5 | C15: 系统运维： ①针对科技项目未导入的单位，辅助导入到系统里 ②集团系统运维 | E15: 闫飞 | F15: 陈伟 | G15: 2025.08.18-08.29 | J15: 已完成
B16: 6 | C16: 功能讨论: ①批量操作数据实现弹窗或者进度条展示功能实现方案讨论 ②针对讨论的功能完成设计 | E16: 李翠霞 | F16: 闫飞、李鑫、李春阳、刘畅 | G16: 2025.08.18-08.22 | J16: 未启动
B17: 7 | C17: 系统开发： ②动态、风险、问题、等模块独自增加标签方案设计及功能开发 | E17: 闫飞 | G17: 2025.08.11-08.29 | H17: 已完成标签标记功能。 | J17: 进行中
B18: 8 | C18: 系统梳理： ①完成为中台提供数据的10个页面的梳理，和字段缺失的补充。 | E18: 闫飞 | G18: 2025.08.18-08.22 | J18: 已完成
B20: 上期出现的问题/风险
B21: 序号 | C21: 问题/风险描述 | E21: 可能的影响 | H21: 解决途径和措施
B23: =CONCATENATE("本期工作计划（",日期!B2,"）")
B24: 序号 | C24: 名称 | E24: 负责人 | F24: 配合 | G24: 时间 | H24: 任务交付 | I24: 说明
B25: 1 | C25: 系统测试： ①集团版成果模块测试 | E25: 牛诩 | F25: 闫飞 | G25: 2025.08.25-08.29
B26: 2 | C26: 系统测试： ①科技项目导入功能完善测试 | E26: 牛诩 | F26: 李鑫、闫飞 | G26: 2025.08.25-08.29 | H26: 1.支持导出本单位项目。 2.支持在导出的excel修改后继续导入系统，仅对修改项进行更新。 3.支持导入时对某个字段报错进行提示（由于导入时间过长和异步导入问题此功能可能无法实现） 4.支持根据本单位项目名称进行排查避免重复导入问题。
B27: 3 | C27: 系统开发： ②动态、风险、问题、等模块独自增加标签方案设计及功能开发 | E27: 闫飞 | G27: 2025.08.25-08.29
B28: 4 | C28: 系统开发： ①两级同步系统网络已经调通，完成227到集团数据的报送功能 ②因集团版项目标签改造，两级项目报送增加标签功能 | E28: 李鑫 | F28: 杨李凯、闫飞、陈伟 | G28: 2025.08.25-08.29 | H28: transfer应用在GCH环境下读取路径存在问题，需要重新部署调试
B29: 5 | C29: 系统开发： 合并平台分支并测试 | E29: 闫飞 | F29: 牛诩 | G29: 2025.08.25-08.29 | H29: 合并最新平台分支
B30: 6 | C30: 系统开发： 组织机构需求与平台沟通并进行优化及开发。 | E30: 闫飞 | G30: 2025.08.25-08.29
B31: 7 | C31: 功能讨论: ①批量操作数据实现弹窗或者进度条展示功能实现方案讨论 ②针对讨论的功能完成设计 | E31: 李翠霞 | F31: 闫飞、李鑫、李春阳、刘畅 | G31: 2025.08.25-08.29
B32: 8 | C32: 数据导入： ①科技项目数据导入 | E32: 闫飞 | F32: 李鑫 | G32: 2025.08.25-08.29 | H32: 提交到科信部的项目清单数据导入
B34: 暂时搁置工作
B35: 序号 | C35: 主要内容 | F35: 搁置原因与处理方案 | I35: 预期处理时间 | J35: 负责人
B36: 1 | C36: 文件上传问题排查 | F36: 因两级同步功能开发测试和GP系统上线导致此任务暂停 | J36: 闫飞

Sheet 周报_IC（双周，周一）
B1: 项目管理系统项目工作周报
B2: 编号：
B3: 项目名称 | D3: 信息中心项目管理系统 | G3: 本期起止日期 | H3: =日期!B10
B4: 项目阶段 | D4: 系统上线运行 | G4: 项目状态 | H4: 正常
B5: 阶段目标 | D5: ①系统已有内容持续优化 ②新需求开发上线
B6: 上期工作综述 | D6: ①系统使用维护。 ②知识产权管理模块更新 ③两级功能开发
B7: 本期重点工作 | D7: ①系统使用维护。 ②两级模块测试、更新。
B9: =CONCATENATE("上期工作总结（",日期!B11,"）")
B10: 序号 | C10: 名称 | E10: 负责人 | F10: 配合 | G10: 时间 | H10: 任务交付 | I10: 说明 | J10: 完成情况
B11: 1 | C11: 系统使用支持 | E11: 李春阳 | F11: 李翠霞 | G11: 2025.08.18-08.29
B12: 2 | C12: 系统开发： ①穿透监管所需业务功能迁移、开发 ②两级监管相关功能开发 | E12: 李鑫 | F12: 李春阳、韩笑 | G12: 2025.08.18-08.29
B13: 3 | C13: 需求沟通： ①知识产权管理办法更新 ②项目、合同和定密等功能优化 | E13: 李春阳 | G13: 2025.07.28-08.08 | H13: 1）讨论确定成果管理修改内容及开发计划 2）讨论确定项目、合同和定密内容调整需求 共计22条需求和数据处理，确认本次版本更新计划解决12条，其中自定义定密导出、项目编号回写至定密信息已与本周完成，成果管理内容调整于下周进行。 | J13: 已完成
B14: 4 | C14: 系统开发： 组件功能完善 | E14: 李春阳 | G14: 2025.07.28-08.08 | H14: 1）基于本地缓存的多索引查询支持（待完善集群功能） 2）Excel导入支持多行导入 3）Excel导出支持单格多类型导出、支持单格多行处理、自适应高度等 | J14: 已完成
B15: 5
B17: 上期出现的问题/风险
B18: 序号 | C18: 问题描述 | E18: 可能的影响 | H18: 解决途径和措施
B19: 1
B21: =CONCATENATE("本期工作计划（",日期!B10,"）")
B22: 序号 | C22: 名称 | E22: 负责人 | F22: 配合 | G22: 时间 | H22: 任务交付 | I22: 说明
B23: 1 | C23: 系统使用支持 | E23: 李春阳 | F23: 李翠霞 | G23: 2025.07.28-08.08
B24: 2 | C24: 系统开发： ①知识产权管理办法更新 ②项目、合同和定密等功能优化 | E24: 韩笑 | F24: 李春阳 | G24: 2025.08.25-08.29 | H24: 完成本次升级计划内共计12项开发和运维内容。 | I24: 待测试稳定通过后择机部署上线
B25: 3 | C25: 系统测试： ③两级管理模块上线测试（1.31） | E25: 李鑫 | F25: 李春阳 | G25: 2025.9.01-9.12
B26: 4 | C26: 系统测试： ③两级管理模块上线测试（1.31权限开通） | E26: 李翠霞 | F26: 陈伟 | G26: 2025.9.01-9.12
B28: 暂时搁置工作
B29: 序号 | C29: 主要内容 | F29: 搁置原因与处理方案 | I29: 预期处理时间 | J29: 负责人
B30: 1 | C30: 项目空间增加操作按钮权限与项目列表对应权限保持一致 | F30: 前端数据刷新交互存在问题，待明确实现方案 | J30: 肖为胜
B31: 2 | C31: 项目、立项、合同模块升级方案设计 | F31: 目前已经完成设计，后续要结合科研处的意见进行讨论优化 | J31: 李春阳
B32: 3 | C32: 首页统计内容优化 | F32: 先根据最新经费管理要求确定系统升级方案，再确定首页 统计方案 | J32: 李翠霞
B33: 4 | C33: IC服务器（含30.1）与GP服务器网络打通手续 | F33: 两级功能完成开发后再申请 | J33: 李翠霞

Sheet 周报_SYS（周一）
B1: 项目管理系统项目工作周报
B2: 编号：
B3: 项目名称 | D3: 基础平台 | G3: 本期起止日期 | H3: 2026-02-02-2026-02-06
B4: 项目阶段 | D4: 完成平台日常升级、维护与各项临时工作 | G4: 项目状态 | H4: 正常
B5: 阶段目标
B6: 上期工作综述 | D6: {{summary_of_previous_work}}
B7: 本期重点工作 | D7: {{key_tasks_of_this_period}}
B11: 上期工作总结（2026-01-26-2026-01-30）
B12: 序号 | C12: 名称 | E12: 负责人 | F12: 配合 | G12: 时间 | H12: 任务交付 | I12: 说明 | J12: 完成情况
B13: 1 | C13: 功能bug处理与功能优化 | D13: PLTSOM-678 | E13: 于姗姗 | G13: 2026-01-26-2026-01-30 | J13: 待办
B14: 2 | C14: ZB数据指标管理插件的完善 | D14: PLTSOM-616 | E14: 于姗姗 | G14: 2026-01-26-2026-01-30 | H14: # Zb体系的select选择范围根据当前装备所映射的视图进行选择 # 修改zb系统所有简写名称 # 增加新增序号和编号类型校验功能 # 增加弹窗必填校验 # 增加按钮样式 # Zb数据元组件列表显示在初始化展示时复合指标的完全限定之变的详情展示修改 # 指标管理新增指标指标库弹窗添加判重校验 | J14: 已提交
B15: 3 | C15: 参照UI反馈优化平台样式 | D15: PLTSOM-573 | E15: 于姗姗 | G15: 2026-01-26-2026-01-30 | H15: # 项目管理系统样式调整,图表展示错位问题调整 # 创新中心门户配置产品中心和应用中心数据配置 | J15: 处理中
B16: 4 | C16: 项目管理项目 - 查看需求目录（跳转页面） | D16: PLTSOM-746 | E16: 于姗姗 | G16: 2026-01-26-2026-01-30 | J16: 待办
B17: 5 | C17: 仪表板隐藏， 仪表板的代办列表加到首页-个人中心 | D17: PLTSOM-749 | E17: 于姗姗 | G17: 2026-01-26-2026-01-30 | J17: 待办
B18: 6 | C18: DL各环境运维部署 | D18: PLTSOM-671 | E18: 周昊 | G18: 2026-01-26-2026-01-30 | H18: *1.开发环境* (1)57研发流程同步用户报错，经外协人员到场排查，问题已解决。 (2)811机房两台通用机重装操作系统后，原来的JDK版本出现了不兼容的问题，后端代码无法部署，东方通实例添加代码加密的启动参数后无法启动，需要更新兼容的JDK版本。 (3)研发流程系统部署文档已初步完成，需要调整格式。 *2.创新中心环境* (1)模型验证分系统已经更新。 (2)研发流程需要更新，在导入解压更新文件的时候，文件资源管理器卡死，D盘消失，只能强制重启。 *3.201环境* 无变化 *4.70环境* 70所知识管理分系统，新建知识库提示找不到流程，在开发环境重新部署测试，没有此问题，已经将问题反馈给相关负责人，需到现场排查。 | J18: 待办
B19: 7 | C19: 一键化部署脚本优化 | D19: PLTSOM-118 | E19: 周昊 | G19: 2026-01-26-2026-01-30 | H19: 1.已解决在ARM架构下安装es、mq时遇到的问题，并针对部署脚本进行了优化。 2.修改了相关的配置文件及环境变量，使其能够适配系统环境。 3.修改后的环境部署包已上传至开发网。 | J19: 处理中
B20: 8 | C20: DL各系统部署文档优化，部署包上传。 | D20: PLTSOM-630 | E20: 周昊 | G20: 2026-01-26-2026-01-30 | H20: ||序号||配置项||分系统||完成日期|| |01|管理平台|1.1 门户+框架+项目+协同| | | | |1.2 研发流程| | | | |1.3 工具集成| | | | |1.4 模型数据| | | | |1.5数字线索| | | | |1.6模型验证| | | | |1.7知识管理| | |02|运行平台| | | |03|机动验证| | | |04|ZZ验证| | | |05|数字空间| | | |06|JS需求| | | |07|ZZ设计| | | |08|仿真优化| | | |09|需求建模| | | |10|电子手册| | | |11|功能原理| | | |12|数字维保| | | |13|虚拟装配| | | |14|JD维修| | | |15|BD维修| | | |16|引导维护| | | |17|远程维修| | | | J20: 待办
B21: 9 | C21: 格尔网关单点登录调试 | D21: PLTSOM-627 | E21: 常松松 | F21: 杨李凯 | G21: 2026-01-26-2026-01-30 | H21: 线上已完成配置，等南团访问环境搭建好后进行正式测试 | J21: 验证中
B22: 10 | C22: 柔性对象平台视图切换由浏览器级缓存改为页面级缓存 | D22: PLTSOM-730 | E22: 常松松 | G22: 2026-01-26-2026-01-30 | J22: 待办
B23: 11 | C23: 支撑ZB模板与ZB历史数据录入 | D23: PLTSOM-679 | E23: 张德宝 | G23: 2026-01-26-2026-01-30 | H23: 1.开发了批量导入装备指标模板的接口 2.支撑完成了车、弹两个领域的装备指标模板的搭建 3.支撑进行了8型车、6型弹装备的指标治理与录入 4.结合近期应用场景，搭建权限控制机制 | J23: 待办
B24: 12 | C24: ZB数据管理系统开发 | D24: PLTSOM-559 | E24: 张德宝 | G24: 2026-01-26-2026-01-30 | H24: 1.完成填报进展报告与领域进展统计的上线 2.完成生产环境数据中台的集成，具备技术状态 3.支撑数据填报、任务分发，更新用户手册 4.确定数据看板方案 5.组织数据应用分析模块（检索对比、装备设计、分类占比与增值管理、数据看板）的开发 | J24: 处理中
B25: 13 | C25: zb数据应用功能（检索、对比、智能设计、分系统价格占比、数据看板） | D25: PLTSOM-677 | E25: 张德宝 | G25: 2026-01-26-2026-01-30 | H25: 1.与bky耿博讨论并梳理了装备检索、对比、智能设计等功能的需求 | J25: 待办
B26: 14 | C26: 装备数据采集功能完善 | D26: PLTSOM-676 | E26: 张德宝 | G26: 2026-01-26-2026-01-30 | H26: 1.梳理需求、设计业务逻辑 2.开发装备数据采集模块 3.编写用户手册 | J26: 待办
B27: 15 | C27: MinIO集群验证、部署、编写部署文档 | D27: PLTSOM-725 | E27: 杨李凯 | G27: 2026-01-26-2026-01-30 | H27: 1.windows版本集群部署测试通过 2.linux版本 配置验证未通过 3.专用机 集群待验证 | J27: 待办
B28: 16 | C28: 需求管理系统与项目管理系统集成 | D28: PLTSOM-430 | E28: 杨李凯 | G28: 2026-01-26-2026-01-30 | H28: 1.根据项目新建需求项目 2.计划查询对应项目的文件列表 3.根据文件查看所有需求 4.绑定需求（添加、修改、删除关联），回显绑定需求 | J28: 待办
B29: 17 | C29: 平台长接口异步机制的设计与开发 | D29: PLTSOM-574 | E29: 杨李凯 | G29: 2026-01-26-2026-01-30 | H29: 基于“两级同步-远程部署”梳理了异步交互实例 | J29: 已提交
B30: 18 | C30: 项目立项通过直接添加需求目录 | D30: PLTSOM-747 | E30: 杨李凯 | G30: 2026-01-26-2026-01-30 | J30: 待办
B31: 19 | C31: WBS列表创建需求按钮挪到计划编制菜单 | D31: PLTSOM-748 | E31: 杨李凯 | G31: 2026-01-26-2026-01-30 | J31: 待办
B32: 20 | C32: 需求查看计划 | D32: PLTSOM-750 | E32: 杨李凯 | G32: 2026-01-26-2026-01-30 | J32: 待办
B33: 21 | C33: 需求目录查看项目详情 | D33: PLTSOM-751 | E33: 杨李凯 | G33: 2026-01-26-2026-01-30 | J33: 待办
B34: 22 | C34: 目录绑定项目 | D34: PLTSOM-752 | E34: 杨李凯 | G34: 2026-01-26-2026-01-30 | J34: 待办
B35: 23 | C35: 备份检查情况 | D35: PLTSOM-418 | E35: 王佳程 | G35: 2026-01-26-2026-01-30 | H35: *2026年1月备份检查情况* ||系统||IP||备份方式||备份目录||检查人||检查日期|| |GP|33|增量|jpky/备份/数据附件备份|王佳程|2026.1.21| | |32|增量|jpky/备份/数据附件备份|王佳程|2026.1.21| | |31|增量|jpky/备份/数据附件备份|王佳程|2026.1.21| |IC|24|增量|jpky/数据附件备份|王佳程|2026.1.21| | |23|增量|jpky/数据附件备份|王佳程|2026.1.21| | |22|增量|jpky/数据附件备份|王佳程|2026.1.21| |ACC|160|增量|D/PMSBKY/财务备份|王佳程|2026.1.21| | |32|增量|jpky/财务备份|王佳程|2026.1.21| GP： 增量3-4G，全量60G IC： 增量1-2G，全量40G ACC：增量1-2G，全量30G | J35: 处理中
B36: 24 | C36: SM环境建设推进 | D36: PLTSOM-734 | E36: 王佳程 | G36: 2026-01-26-2026-01-30 | H36: *2026年1月22日：* 1）已和赵赫森联系，进入中心网需先办理设备入账； 2）等待领导沟通后确认方案。 *2026年1月20日：* 1）已和陈雷确定方案，先建立独立局域网，本周搬入； 2）同步进行中心SM网建设。 *2026年1月16日：* 1）已和陈雷沟通，因院内工作会，下周搬入、组网； 2）已和长胜沟通，下周协调布线、调试。 *2026年1月13日：* 1）已和陈雷沟通，计划周五前将7台设备搬入小型机房； 2）需同步联系王天安处长，确认建设方案及采购事项。 | J36: 处理中
B37: 25 | C37: 调研dataease和美林数据平台 | D37: PLTSOM-721 | E37: 田广宇 | G37: 2026-01-26-2026-01-30 | H37: # 在内网搭建DataEase [192.168.1.139:8100|http://192.168.1.139:8100/#/login?redirect=/workbranch/index] 账号：admin 密码：DataEase@123456 # 新建数据源验证，校验成功，但未成功连接数据库 # 自定义大屏，生成数据大屏验证 # 可导入海量数据模板（需要先在外网下载好） | J37: 待办
B38: 26 | C38: 协同平台任务开发 | D38: PLTSOM-195 | E38: 田广宇 | F38: 邹雨豪 | G38: 2026-01-26-2026-01-30 | H38: # 协调动力协同70所访问集团数据中心8011、8012端口问题（已解决） # 排查及协调201向70所发送数据失败（已解决） # 动力协同文档模型发放单接收正常；模型创建正常；附件关系正常且可正常下载。 # 动力协同部件模型发放单接收正常；模型创新正常；下级结构正常；相关对象关系正常。 # 动力协同CADdocument发放单接收正常，模型创建正常附件关系正常，可以正常下载。 # 系统监控模块开发完成。 # 系统备份与恢复功能开发完成。 | J38: 处理中
B39: 27 | C39: 与主数据组织机构集成联调 | D39: PLTSOM-696 | E39: 田广宇 | G39: 2026-01-26-2026-01-30 | H39: 1 | J39: 待办
B40: 28 | C40: 系统监控模块开发 | D40: PLTSOM-697 | E40: 田广宇 | G40: 2026-01-26-2026-01-30 | H40: # 监控cpu、内存、磁盘使用率各指标数据监控 # 提供监控相对应的后端接口 | J40: 已提交
B41: 29 | C41: 系统备份与恢复功能开发 | D41: PLTSOM-698 | E41: 田广宇 | G41: 2026-01-26-2026-01-30 | H41: # Minio文件恢复 Linux环境（完成） # Minio文件恢复 Window环境（完成） # 创建Minio部署环境，用于测试环境使用(之前的已给集群测试使用) # IDM文件的备份/IDM文件的恢复 # 数据库备份/数据库恢复流程添加长任务 # 模型对象备份/模型对象恢复添加长任务 # 文件MinIO/IDM备份，文件Minio/IDM恢复添加长任务 # 完成与前端联调联试 | J41: 已提交
B42: 30 | C42: 针对ZB数据管理业务进行压力测试 | D42: PLTSOM-668 | E42: 程浩 | G42: 2026-01-26-2026-01-30 | H42: |194ZB数据性能测试环境| | |CPU信息|/| | |内存信息|32GB| | |测试数据|指标500条/装备10000条| | |性能数据|5S±2.5S/5并发1800S| | |性能指标|样本数|平均响应时间|95%响应时间|异常率| | |编辑该装备10指标|762|0.26s|0.46s|0%| | |查询该装备500指标|762|1.03s|1.29s|0%| | | | | | | | | |性能数据|5S±2.5S/20并发/1800S| | |性能指标|样本数|平均响应时间|95%响应时间|异常率| | |编辑该装备10指标|2961|0.49s|0.96s|0%| | |查询该装备500指标|2952|1.54s|2.37s|0.03%| | | | | | | | | |性能数据|5S±2.5S/50并发1800S| | |性能指标|样本数|平均响应时间|95%响应时间|异常率| | |编辑该装备10指标|6764|0.83s|1.72s|28.81%|msg：调用平台接口异常：操作失败| |查询该装备500指标|6745|2.27s|4.09s|31.46%|msg：调用平台接口异常：操作失败| | | | | | | | |性能数据|5S±2.5S/100并发1800S| | |性能指标|样本数|平均响应时间|95%响应时间|异常率| | |编辑该装备10指标|15198|0.49s|1.97s|68.70%|msg：调用平台接口异常：操作失败| |查询该装备500指标|15155|1.12s|4.40s|72.89%|msg：调用平台接口异常：操作失败| | | | | | | | |性能数据|5S±2.5S/200并发1800S| | |性能指标|样本数|平均响应时间|95%响应时间|异常率| | |编辑该装备10指标| | | | | | |查询该装备500指标| | | | | | | J42: 验证中
B43: 31 | C43: 列表设置中，按钮出参配置需要支持指定字段（目前只支持guid） | D43: PLTSOM-724 | E43: 程浩 | G43: 2026-01-26-2026-01-30 | H43: 新增出参配置：fieldKey !image-2026-01-07-09-00-07-288.png|width=1091,height=323! | J43: 已提交
...

Sheet 周报_质量（周一）
B1: 项目管理系统项目质量周报
B2: 编号：
B3: 本期起止时间 | D3: 2026-02-02-2026-02-06 | H3: 项目状态 | I3: 正常
B4: 阶段目标 | D4: 1.各系统功能、性能正常； 2.各服务器、虚拟机及网络正常运行。
B5: 上期工作综述 | D5: 1.创新中心各系统安装； 2.基础平台测试说明编写。
B6: 本期工作综述 | D6: 1.创新中心各系统部署调试； 2.测试说明、部署手册完善。
B10: 上期工作总结（2026-01-26-2026-01-30）
B11: 序号 | C11: 名称 | F11: 负责人 | G11: 配合 | H11: 时间 | I11: 说明 | J11: 完成情况
B12: 1 | C12: DL各环境运维部署 | F12: 周昊 | H12: 2026-01-26-2026-01-30 | J12: 待办
B13: 2 | C13: 一键化部署脚本优化 | F13: 周昊 | H13: 2026-01-26-2026-01-30 | J13: 处理中
B14: 3 | C14: DL各系统部署文档优化，部署包上传。 | F14: 周昊 | H14: 2026-01-26-2026-01-30 | J14: 待办
B15: 4 | C15: BUG情况统计 | F15: 王佳程 | H15: 2026-01-26-2026-01-30 | J15: 处理中
B16: 5 | C16: 备份检查情况 | F16: 王佳程 | H16: 2026-01-26-2026-01-30 | J16: 处理中
B17: 6 | C17: SM环境建设推进 | F17: 王佳程 | H17: 2026-01-26-2026-01-30 | J17: 处理中
B22: 上期出现的风险或问题
B23: 序号 | C23: 问题/风险描述 | E23: 可能的影响 | H23: 解决途径和措施
B24: 1 | C24: 无
B27: 上期bug总结
B28: 序号 | C28: 系统 | E28: 上期新增 | F28: 当前剩余 | G28: 严重bug | H28: 说明
B29: 1 | C29: 基础平台 | E29: 6 | F29: 8 | G29: 0
B30: 2 | C30: 项目管理 | E30: 40 | F30: 105 | G30: 0
B31: 3 | C31: ZB数据 | E31: 0 | F31: 18 | G31: 0
B32: 4 | C32: 研制过程 | E32: 8 | F32: 8 | G32: 0
B33: 5 | C33: 总计 | E33: 54 | F33: 139 | G33: 0
B34: 本期工作计划（2026-02-02-2026-02-06）
B35: 序号 | C35: 名称 | F35: 负责人 | G35: 配合 | H35: 时间 | I35: 说明
B36: 1 | C36: DL各环境运维部署 | F36: 周昊 | H36: 2026-02-02-2026-02-06 | J36: 待办
B37: 2 | C37: 一键化部署脚本优化 | F37: 周昊 | H37: 2026-02-02-2026-02-06 | J37: 处理中
B38: 3 | C38: 安装部署问题汇总 | F38: 周昊 | H38: 2026-02-02-2026-02-06 | J38: 处理中
B39: 4 | C39: DL各系统部署文档优化，部署包上传。 | F39: 周昊 | H39: 2026-02-02-2026-02-06 | J39: 待办
B40: 5 | C40: 跟技术支持部核对部门台账，审批、打印贴签。 | F40: 王佳程 | H40: 2026-02-02-2026-02-06 | J40: 处理中
B41: 6 | C41: BUG情况统计 | F41: 王佳程 | H41: 2026-02-02-2026-02-06 | J41: 处理中
B42: 7 | C42: 备份检查情况 | F42: 王佳程 | H42: 2026-02-02-2026-02-06 | J42: 处理中
B43: 8 | C43: SM环境建设推进 | F43: 王佳程 | H43: 2026-02-02-2026-02-06 | J43: 处理中
B44: 9 | C44: 创新中心两台服务器上架，空间清理，系统部署。 | F44: 王佳程 | H44: 2026-02-02-2026-02-06 | J44: 待办
B66: 暂时搁置工作
B67: 序号 | C67: 工作内容 | F67: 搁置原因 | I67: 预期处理时间
B68: 1 | C68: 无
B76: 上期服务器备份情况
B77: 备份对象 | C77: IP | D77: 备份方式 | E77: 备份目录 | F77: 备份日期 | G77: 备份人
...

Sheet 周报_CXY（双周-周五发）-本周不发
B1: 项目管理系统项目工作周报
B2: 编号：
B3: 项目名称 | D3: 创新院项目管理系统建设 | G3: 本期起止日期 | H3: =日期!B10
B4: 项目阶段 | D4: 业务功能开发 | G4: 项目状态 | H4: 正常
B5: 阶段目标 | D5: ①版本V3.0功能开发 ②攻坚项目填报 ③两级贯通试点应用
B6: 本期工作综述 | D6: ①完成部门统计、单位统计页面开发 ②和业财接口联调 ③攻坚项目应用支持
B7: 下期重点工作 | D7: ①完成部门统计、单位统计页面开发 ②和业财接口联调 ③攻坚项目应用支持 ④历史项目导入接口开发
B9: =CONCATENATE("本期工作总结（",日期!B10,"）")
B10: 序号 | C10: 名称 | E10: 信息中心 | F10: 配合 | G10: 时间 | H10: 任务交付 | I10: 进展说明 | J10: 完成情况
B11: 1 | C11: 创新院-系统开发 ①单位数据统计中心 | E11: 李鑫 | G11: 2025.05.23-2025.06.06 | H11: 从项目、合同经费、研制计划、问题风险角度来提供数据可视化看板 | J11: 进行中
B12: 2 | C12: 创新院-实施部署 ①对现场试用进行使用支持 | E12: 刘畅 | G12: 2025.05.23-2025.06.06 | H12: 1）对攻坚项目填报进行操作指导 2）处理现场问题 3）编写攻坚项目填报操作说明 | J12: 已完成
B13: 3 | C13: 创新院-系统开发 ②完成部门任务中心 | E13: 闫飞 | G13: 2025.05.23-2025.06.06 | H13: 以卡片式项目列表为主搭建部门项目任务中心页面 | J13: 进行中
B14: 4 | C14: 创新院-系统开发 ③组织机构接口开发 | E14: 李鑫 | G14: 2025.05.23-2025.06.06 | H14: 开通和OA组织机构集成 | J14: 已完成
B15: 5 | C15: 创新院-系统开发 ④消息推送接口开发 | E15: 李鑫 | G15: 2025.05.23-2025.06.06 | H15: 开通和OA的消息推送集成 | J15: 进行中
B17: 本期出现的问题/风险
B18: 序号 | C18: 问题/风险描述 | E18: 可能的影响 | H18: 解决途径和措施
B19: 1 | C19: 系统管理员未确定 | E19: 系统使用过程中，如出现组织机构调整、流程调整、权限调整，可能导致处理不及时。 | H19: 确定三员和业务运维人员后，进行专项培训，并提供实施手册。
B21: =CONCATENATE("下期工作计划（",日期!B12,"）")
B22: 序号 | C22: 名称 | E22: 信息中心 | F22: 配合 | G22: 时间 | H22: 任务交付 | I22: 说明
B23: 1 | C23: 创新院-系统开发 ①单位数据统计中心 | E23: 李鑫 | G23: 2025.06.30-2025.06.06
B24: 2
B25: 3
B26: 4
B27: 5
B29: 暂时搁置工作
B30: 序号 | C30: 主要内容 | F30: 搁置原因与处理方案 | I30: 预期处理时间 | J30: 负责人
B31: 1 | C31: ②交付模块开发 1）交付物对象新建、表单搭建 2）建立合同成果和交付物关系 3）支持交付物分解 4）支持交付物反馈 | F31: 此业务加入后，对目前业务影响较大，等上线稳定后再继续开发 | I31: 2025.06.09 | J31: 刘畅

Sheet 周报_BKY（周一）-本周不发
B1: 项目管理系统项目工作周报
B2: 编号：
B3: 项目名称 | D3: 兵科院GCH项目管理系统 | G3: 本期起止日期 | H3: =日期!B2
B4: 项目阶段 | D4: 系统应用与周期性优化 | G4: 项目状态 | H4: 正常
B5: 阶段目标 | D5: ①系统使用支持
B6: 上期工作综述 | D6: ①系统使用支持 ②经费审计支持
B7: 本期重点工作 | D7: ①系统使用支持 ②经费审计支持
B9: =CONCATENATE("上期工作总结（",日期!B3,"）")
B10: 序号 | C10: 名称 | E10: 负责人 | F10: 配合 | G10: 时间 | H10: 任务交付 | I10: 说明 | J10: 完成情况
B11: 1 | C11: 运维支持： ①系统运维支持 | E11: 陈伟 | F11: 李春阳、闫飞 | G11: 2025.04.27-04.30 | H11: 部分领导缺失调拨单手签章，目前已上传杜萌、申越手签章文件。 | J11: 已完成
B13: 上期出现的问题/风险
B14: 序号 | C14: 问题描述 | E14: 可能的影响 | H14: 解决途径和措施
B15: 1
B16: 2
B18: =CONCATENATE("本期工作计划（",日期!B2,"）")
B19: 序号 | C19: 名称 | E19: 负责人 | F19: 配合 | G19: 时间 | H19: 任务交付 | I19: 说明
B20: 1 | C20: 运维支持： ①系统运维支持 | E20: 陈伟 | F20: 李春阳、闫飞 | G20: 2025.05.06-05.09 | I20: 1.有客户说之前的流程数据查询不出来了。 2.通过查询之前的老服务器流程确实没有数据
B22: 暂时搁置工作
B23: 序号 | C23: 主要内容 | F23: 搁置原因与处理方案 | I23: 预期处理时间 | J23: 负责人
B24: 1 | C24: 系统部署： ①参照部署文档，部署安装服务器环境（完成ha部署，并将服务器连入BKY网内，然后再加入集群，并同步业务代码） | F24: 根据厂商时间确定 | J24: 张德宝 | Y24: file:/D:/willdelete/mupdf/report/jira/jiraCode/rag/services/qa.py

Sheet 日期
A1: 单周周报日期设置
A2: 本期起止日期 | B2: =CONCATENATE(TEXT(DATE(D3,E3,F3),"yyyy.mm.dd"),"-",TEXT(DATE(D3,E3,F3)+F6-G6-1,"yyyy.mm.dd")) | D2: 本期起始年 | E2: 起始月 | F2: 起始日
A3: 上期起止时间（本期前一期） | B3: =CONCATENATE(TEXT(DATE(D3,E3,F3)-D6,"yyyy.mm.dd"),"-",TEXT(DATE(D3,E3,F3)-E6-1,"yyyy.mm.dd")) | D3: 2025 | E3: 8 | F3: 25 | G3: 将红色字体设置为当前周的周一（第一个工作日）对应的日期即可
A4: 下期起止时间（本期后一期） | B4: =CONCATENATE(TEXT(DATE(D3,E3,F3)+F6,"yyyy.mm.dd"),"-",TEXT(DATE(D3,E3,F3)+F6+H6-I6-1,"yyyy.mm.dd"))
D5: 上期天数 | E5: 周末天数 | F5: 本期天数 | G5: 本期末周周末天数 | H5: 下期天数 | I5: 下期末周周末天数
D6: 7 | E6: 2 | F6: 7 | G6: 2 | H6: 7 | I6: 2
D7: 上次发周报日期到本次发周报日期间隔天数 | E7: 上期最后一个工作日到本期发周报日期之间的休息日天数，通常为2天（周六、周日） | F7: 本次发周报日期到本期最后一个工作日间的自然日天数，如两周，含两周间的休息日 | G7: 本次周报最后一周周末的天数，通常为2天（周六、周日） | H7: 以本期起止日期为参照，下一周期的天数，含周末 | I7: 以本期起止日期为参照，下一周期的周末天数
A9: 双周周报日期
A10: 本期起止日期 | B10: =CONCATENATE(TEXT(DATE(D11,E11,F11),"yyyy.mm.dd"),"-",TEXT(DATE(D11,E11,F11)+F14-G14-1,"yyyy.mm.dd")) | D10: 本期起始年 | E10: 起始月 | F10: 起始日
A11: 上期起止时间（本期前一期） | B11: =CONCATENATE(TEXT(DATE(D11,E11,F11)-D14,"yyyy.mm.dd"),"-",TEXT(DATE(D11,E11,F11)-E14-1,"yyyy.mm.dd")) | D11: 2025 | E11: 9 | F11: 1 | G11: 将红色字体设置为当前周的周一（第一个工作日）对应的日期即可
A12: 下期起止时间（本期后一期） | B12: =CONCATENATE(TEXT(DATE(D11,E11,F11)+F14,"yyyy.mm.dd"),"-",TEXT(DATE(D11,E11,F11)+F14+H14-I14-1,"yyyy.mm.dd"))
D13: 上期天数 | E13: 周末天数 | F13: 本期天数 | G13: 本期末周周末天数 | H13: 下期天数 | I13: 下期末周周末天数
D14: 14 | E14: 2 | F14: 14 | G14: 2 | H14: 14 | I14: 2
D15: 上次发周报日期到本次发周报日期间隔天数 | E15: 上期最后一个工作日到本期发周报日期之间的休息日天数，通常为2天（周六、周日） | F15: 本次发周报日期到本期最后一个工作日间的自然日天数，如两周，含两周间的休息日 | G15: 本次周报最后一周周末的天数，通常为2天（周六、周日） | H15: 以本期起止日期为参照，下一周期的天数，含周末 | I15: 以本期起止日期为参照，下一周期的周末天数
